<?xml version="1.0"?>
	<robot name="robot_chaine">

		<!-- lien 1 -->
		<link name="base_link">
			<visual>
				<origin rpy="0 0 0" xyz="0 0 0"/>
				<geometry>
					<box size="0.4 0.4 0.4"/>
			   </geometry>
			</visual>

			<collision>
				<origin rpy="0 0 0" xyz="0 0 0"/>
				<geometry>
					<box size="0.4 0.4 0.4"/>
			   </geometry>
    		</collision>
		</link>
		<!-- fin lien 1 -->

		<!-- lien 2--> 
		<link name="up_link">
			<visual>
				<origin rpy="0 0 0" xyz="0.4 0 0.6"/>
				<geometry>
					<box size="0.4 0.4 1.6"/>
			   </geometry>
			</visual>
			<collision>
				<origin rpy="0 0 0" xyz="0.4 0 0.6"/>
				<geometry>
					<box size="0.4 0.4 1.6"/>
		      </geometry>
	    	</collision>
		</link>
		<!--  fin lien 2 -->
		
		<!-- lien 3--> 
		<link name="tail_link">
			<visual>
				<origin rpy="0 0 0.50" xyz="0.4 0 2.3"/>
				<geometry>
					<box size="0.4 0.4 1.6"/>
			   </geometry>
			</visual>
			<collision>
				<origin rpy="0 0 0.5" xyz="0.4 0 2.3"/>
				<geometry>
					<box size="0.4 0.4 1.6"/>
		      </geometry>
	    	</collision>
		</link>
		<!--  fin lien 3 -->

   <joint name="base_to_up" type="fixed">
       <parent link="base_link"/>
       <child link="up_link"/>
			<origin xyz="0 0 0"/>
   </joint>

	<joint name="up_to_tail" type="revolute">
		<parent link="up_link"/>
		<child link="tail_link"/>
		<axis xyz="1 0 0"/>
		<origin xyz="0 0 0"/>
		<limit effort="1000" lower="-1.2" upper="1.2" velocity="0.5"/>
	</joint>

	</robot>
